<?xml version="1.0"?>
<robot name="second">
  <link name="base_link">
    <visual>
      <geometry>
        <cylinder length="0.6" radius="0.25" />
      </geometry>
    </visual>
    <collision>
      <geometry>
        <cylinder length="0.6" radius="0.25" />
      </geometry>
    </collision>
    <inertial>
      <mass value="0.25" />
      <inertia ixx="0.0003" iyy="0.0003" izz="0.0003" ixy="0" ixz="0" iyz="0" />
    </inertial>
  </link>
  <link name="wheel1">
    <visual>
      <geometry>
        <cylinder length="0.2" radius="0.25" />
      </geometry>
    </visual>
    <collision>
      <geometry>
        <cylinder length="0.2" radius="0.25" />
      </geometry>
    </collision>
    <inertial>
      <mass value="0.25" />
      <inertia ixx="0.0003" iyy="0.0003" izz="0.0003" ixy="0" ixz="0" iyz="0" />
    </inertial>
  </link>
  <link name="wheel2">
    <visual>
      <geometry>
        <cylinder length="0.2" radius="0.25" />
      </geometry>
    </visual>
    <collision>
      <geometry>
        <cylinder length="0.2" radius="0.25" />
      </geometry>
    </collision>
    <inertial>
      <mass value="0.25" />
      <inertia ixx="0.0003" iyy="0.0003" izz="0.0003" ixy="0" ixz="0" iyz="0" />
    </inertial>
  </link>

  <joint name="base_to_wheel1" type="revolute">
    <parent link="base_link" />
    <child link="wheel1" />
    <axis xyz="0 0 1" />
    <limit effort="10" upper="0" lower="10" velocity="1" />
    <origin rpy="0 0 0" xyz="0 0.5 0.2" />
  </joint>

  <joint name="base_to_wheel2" type="revolute">
    <parent link="base_link" />
    <child link="wheel2" />
    <axis xyz="0 0 1" />
    <limit effort="10" upper="0" lower="10" velocity="1" />
    <origin rpy="0 0 0" xyz="0 0.5 -0.2" />
  </joint>
</robot>