<?xml version="1.0"?>
<robot name="myfirst">
  <link name="body">
    <visual>
      <geometry>
        <box size="3 5 2" />
      </geometry>
    </visual>
    <collision>
      <geometry>
        <box size="3 5 2" />
      </geometry>
    </collision>
    <inertial>
      <mass value="0.25" />
      <inertia ixx="0.0003" iyy="0.0003" izz="0.0003" ixy="0" ixz="0" iyz="0" />
    </inertial>
  </link>

  <link name="front_right_wheel">
    <visual>
      <geometry>
        <cylinder length="0.1" radius="1" />
      </geometry>
    </visual>
    <collision>
      <geometry>
        <cylinder length="0.1" radius="1" />
      </geometry>
    </collision>
    <inertial>
      <mass value="0.25" />
      <inertia ixx="0.0003" iyy="0.0003" izz="0.0003" ixy="0" ixz="0" iyz="0" />
    </inertial>
  </link>

  <link name="front_left_wheel">
    <visual>
      <geometry>
        <cylinder length="0.1" radius="1" />
      </geometry>
    </visual>
    <collision>
      <geometry>
        <cylinder length="0.1" radius="1" />
      </geometry>
    </collision>
    <inertial>
      <mass value="0.25" />
      <inertia ixx="0.0003" iyy="0.0003" izz="0.0003" ixy="0" ixz="0" iyz="0" />
    </inertial>
  </link>

  <link name="back_right_wheel">
    <visual>
      <geometry>
        <cylinder length="0.1" radius="1" />
      </geometry>
    </visual>
    <collision>
      <geometry>
        <cylinder length="0.1" radius="1" />
      </geometry>
    </collision>
    <inertial>
      <mass value="0.25" />
      <inertia ixx="0.0003" iyy="0.0003" izz="0.0003" ixy="0" ixz="0" iyz="0" />
    </inertial>
  </link>

  <link name="back_left_wheel">
    <visual>
      <geometry>
        <cylinder length="0.1" radius="1" />
      </geometry>
    </visual>
    <collision>
      <geometry>
        <cylinder length="0.1" radius="1" />
      </geometry>
    </collision>
    <inertial>
      <mass value="0.25" />
      <inertia ixx="0.0003" iyy="0.0003" izz="0.0003" ixy="0" ixz="0" iyz="0" />
    </inertial>
  </link>

  <joint name="f_r_wheel" type="revolute">
    <parent link="body" />
    <child link="front_right_wheel" />
    <axis xyz="0 0 1" />
    <limit effort="10" upper="0" lower="10" velocity="1" />
    <origin rpy="1.5708 0 1.5708" xyz="1.5 2 -0.5" />
  </joint>

  <joint name="f_l_wheel" type="revolute">
    <parent link="body" />
    <child link="front_left_wheel" />
    <axis xyz="0 0 1" />
    <limit effort="10" upper="0" lower="10" velocity="1" />
    <origin rpy="1.5708 0 1.5708" xyz="-1.5 2 -0.5" />
  </joint>

  <joint name="b_r_wheel" type="revolute">
    <parent link="body" />
    <child link="back_right_wheel" />
    <axis xyz="0 0 1" />
    <limit effort="10" upper="0" lower="10" velocity="1" />
    <origin rpy="1.5708 0 1.5708" xyz="1.5 -2 -0.5" />
  </joint>

  <joint name="b_l_wheel" type="revolute">
    <parent link="body" />
    <child link="back_left_wheel" />
    <axis xyz="0 0 1" />
    <limit effort="10" upper="0" lower="10" velocity="1" />
    <origin rpy="1.5708 0 1.5708" xyz="-1.5 -2 -0.5" />
  </joint>
</robot>